Workbook

Sheet Lists
A1: Activity Names | B1: Category | C1: Auto Announcement | D1: Auto Expo | E1: Branding | F1: Canopy | G1: Dealer Meet | H1: Demo Van | I1: Digital | J1: E-Rickshaw Activity | K1: Gift | L1: Hoarding | M1: Inauguration | N1: Leaflet Distribution | O1: LED Screen Display | P1: Mall Activity | Q1: Mela | R1: Newspaper | S1: Newspaper Insertion | T1: Promotional Material | U1: Radio Advertisement | V1: Referral Program | W1: Sports Sponsorship | X1: Theatre Advertisement | Y1: Wall Poster
A2: Auto Announcement | B2: ATL | C2: Auto Announcement | D2: Auto Expo | E2: 2D Gate | F2: Canopy | G2: Dealer Meet | H2: Demo Van | I2: Facebook | J2: E-Rickshaw Activity | K2: Air Conditioner (AC) | L2: Hoarding | M2: Dealer Inauguration | N2: Leaflet Distribution | O2: LED Screen Display | P2: Mall Activity | Q2: Mela | R2: Amar Ujala | S2: Paper Insertion | T2: Material Supply | U2: Radio | V2: Referral | W2: IPL | X2: Theatre Advertisement | Y2: Wall Poster
A3: Auto Expo | B3: BTL | E3: 3D Gate | I3: Instagram | K3: Air Fryer | R3: Daily Thanthi | W3: PKL
A4: Branding | B4: ATL | E4: Arch Gate | I4: YouTube | K4: Electric Iron | R4: Dainik Bhaskar
A5: Canopy | B5: BTL | E5: Auto Branding | K5: Fan | R5: Dainik Jagran
A6: Dealer Meet | B6: ATL | E6: Banner | K6: Geyser | R6: Hindustan Times
A7: Demo Van | B7: BTL | E7: Bus Branding | K7: Gold Coin | R7: Lokmat
A8: Digital | B8: ATL | K8: LED TV | R8: Loksatta
A9: E-Rickshaw Activity | B9: BTL | K9: Mixer Grinder | R9: Maharashtra Times
A10: Gift | B10: ATL | K10: Trolley Bag | R10: Sakal
A11: Hoarding | B11: ATL | K11: Washing Machine | R11: The Hindu
A12: Inauguration | B12: BTL | R12: Times of India
A13: Leaflet Distribution | B13: ATL
A14: LED Screen Display | B14: ATL
A15: Mall Activity | B15: BTL
A16: Mela | B16: BTL
A17: Newspaper | B17: ATL
A18: Newspaper Insertion | B18: ATL
A19: Promotional Material | B19: BTL
A20: Radio Advertisement | B20: ATL
A21: Referral Program | B21: ATL
A22: Sports Sponsorship | B22: ATL
A23: Theatre Advertisement | B23: ATL
A24: Wall Poster | B24: ATL

Sheet Activities
A1: ★ REQUIRED | B1: ★ REQUIRED | C1: ★ REQUIRED | D1: 🔒 Auto | E1: ★ REQUIRED | F1: Optional | G1: ★ REQUIRED | H1: ★ REQUIRED | I1: ★ REQUIRED | J1: ★ REQUIRED | K1: Optional | L1: ★ REQUIRED | M1: 🔒 Auto | N1: 🔒 Auto | O1: Optional
A2: Activity Name * | B2: Subcategory | C2: QTY | D2: Category (ATL/BTL) | E2: Lead Target | F2: Sales % | G2: Retail Target | H2: Start Date (DD-MM-YYYY) | I2: End Date (DD-MM-YYYY) | J2: Budget (₹) | K2: Special Approval Budget (₹) | L2: BGauss Share % | M2: BGauss Amount (₹) | N2: Total Budget (₹) | O2: Remarks
A3: Select ▼ (23 activities) | B3: Select ▼ (auto-filtered by col A) | C3: 1–max | D3: 🔒 Auto VLOOKUP | E3: Number | F3: e.g. 3% | G3: Auto or manual | H3: DD-MM-YYYY | I3: DD-MM-YYYY | J3: e.g. 50000 | K3: 0 if none | L3: 100/70/50 ▼ | M3: =(J+K)×L÷100 -> 0 | N3: =J+K -> 0 | O3: Optional
A4: Auto Announcement | B4: Auto Announcement | C4: 1 | D4: =IF(A4="","",IFERROR(VLOOKUP(A4,Lists!$A$2:$B$24,2,0),"")) -> ATL | E4: 20 | H4: 01-07-2026 | I4: 31-07-2026 | J4: 50000 | K4: 0 | L4: 100 | M4: =IF(J4="","",ROUND((J4+K4)*L4/100,0)) -> 50000 | N4: =IF(J4="","",J4+K4) -> 50000 | O4: EXAMPLE — delete before import
A5: Auto Expo | B5: Auto Expo | C5: 1 | D5: =IF(A5="","",IFERROR(VLOOKUP(A5,Lists!$A$2:$B$24,2,0),"")) -> BTL | E5: 20 | H5: 01-07-2026 | I5: 31-07-2026 | J5: 50000 | K5: 0 | L5: 100 | M5: =IF(J5="","",ROUND((J5+K5)*L5/100,0)) -> 50000 | N5: =IF(J5="","",J5+K5) -> 50000
A6: Branding | B6: 2D Gate | C6: 1 | D6: =IF(A6="","",IFERROR(VLOOKUP(A6,Lists!$A$2:$B$24,2,0),"")) -> ATL | E6: 20 | H6: 01-07-2026 | I6: 31-07-2026 | J6: 50000 | K6: 0 | L6: 100 | M6: =IF(J6="","",ROUND((J6+K6)*L6/100,0)) -> 50000 | N6: =IF(J6="","",J6+K6) -> 50000
D7: =IF(A7="","",IFERROR(VLOOKUP(A7,Lists!$A$2:$B$24,2,0),"")) | M7: =IF(J7="","",ROUND((J7+K7)*L7/100,0)) | N7: =IF(J7="","",J7+K7)
D8: =IF(A8="","",IFERROR(VLOOKUP(A8,Lists!$A$2:$B$24,2,0),"")) | M8: =IF(J8="","",ROUND((J8+K8)*L8/100,0)) | N8: =IF(J8="","",J8+K8)
D9: =IF(A9="","",IFERROR(VLOOKUP(A9,Lists!$A$2:$B$24,2,0),"")) | M9: =IF(J9="","",ROUND((J9+K9)*L9/100,0)) | N9: =IF(J9="","",J9+K9)
D10: =IF(A10="","",IFERROR(VLOOKUP(A10,Lists!$A$2:$B$24,2,0),"")) | M10: =IF(J10="","",ROUND((J10+K10)*L10/100,0)) | N10: =IF(J10="","",J10+K10)
D11: =IF(A11="","",IFERROR(VLOOKUP(A11,Lists!$A$2:$B$24,2,0),"")) | M11: =IF(J11="","",ROUND((J11+K11)*L11/100,0)) | N11: =IF(J11="","",J11+K11)
D12: =IF(A12="","",IFERROR(VLOOKUP(A12,Lists!$A$2:$B$24,2,0),"")) | M12: =IF(J12="","",ROUND((J12+K12)*L12/100,0)) | N12: =IF(J12="","",J12+K12)
D13: =IF(A13="","",IFERROR(VLOOKUP(A13,Lists!$A$2:$B$24,2,0),"")) | M13: =IF(J13="","",ROUND((J13+K13)*L13/100,0)) | N13: =IF(J13="","",J13+K13)
D14: =IF(A14="","",IFERROR(VLOOKUP(A14,Lists!$A$2:$B$24,2,0),"")) | M14: =IF(J14="","",ROUND((J14+K14)*L14/100,0)) | N14: =IF(J14="","",J14+K14)
D15: =IF(A15="","",IFERROR(VLOOKUP(A15,Lists!$A$2:$B$24,2,0),"")) | M15: =IF(J15="","",ROUND((J15+K15)*L15/100,0)) | N15: =IF(J15="","",J15+K15)
D16: =IF(A16="","",IFERROR(VLOOKUP(A16,Lists!$A$2:$B$24,2,0),"")) | M16: =IF(J16="","",ROUND((J16+K16)*L16/100,0)) | N16: =IF(J16="","",J16+K16)
D17: =IF(A17="","",IFERROR(VLOOKUP(A17,Lists!$A$2:$B$24,2,0),"")) | M17: =IF(J17="","",ROUND((J17+K17)*L17/100,0)) | N17: =IF(J17="","",J17+K17)
D18: =IF(A18="","",IFERROR(VLOOKUP(A18,Lists!$A$2:$B$24,2,0),"")) | M18: =IF(J18="","",ROUND((J18+K18)*L18/100,0)) | N18: =IF(J18="","",J18+K18)
... D53: =IF(A53="","",IFERROR(VLOOKUP(A53,Lists!$A$2:$B$24,2,0),"")) | M53: =IF(J53="","",ROUND((J53+K53)*L53/100,0)) | N53: =IF(J53="","",J53+K53)

Sheet Subcategory Reference
A1: Activity Master — Subcategory & Max QTY Reference
A2: Activity Name | B2: ATL / BTL | C2: Subcategory | D2: Max QTY
A3: Auto Announcement | B3: ATL | C3: Auto Announcement | D3: 5
A4: Auto Expo | B4: BTL | C4: Auto Expo | D4: 5
A5: Branding | B5: ATL | C5: 2D Gate | D5: 20
C6: 3D Gate | D6: 20
C7: Arch Gate | D7: 20
C8: Auto Branding | D8: 20
C9: Banner | D9: 20
C10: Bus Branding | D10: 20
A11: Canopy | B11: BTL | C11: Canopy | D11: 12
A12: Dealer Meet | B12: ATL | C12: Dealer Meet | D12: 5
A13: Demo Van | B13: BTL | C13: Demo Van | D13: 5
A14: Digital | B14: ATL | C14: Facebook | D14: 5
C15: Instagram | D15: 5
C16: YouTube | D16: 5
A17: E-Rickshaw Activity | B17: BTL | C17: E-Rickshaw Activity | D17: 5
A18: Gift | B18: ATL | C18: Air Conditioner (AC) | D18: 20
C19: Air Fryer | D19: 20
C20: Electric Iron | D20: 20
C21: Fan | D21: 20
C22: Geyser | D22: 20
C23: Gold Coin | D23: 20
C24: LED TV | D24: 20
C25: Mixer Grinder | D25: 20
C26: Trolley Bag | D26: 20
C27: Washing Machine | D27: 20
A28: Hoarding | B28: ATL | C28: Hoarding | D28: 5
A29: Inauguration | B29: BTL | C29: Dealer Inauguration | D29: 5
A30: Leaflet Distribution | B30: ATL | C30: Leaflet Distribution | D30: 20
A31: LED Screen Display | B31: ATL | C31: LED Screen Display | D31: 5
A32: Mall Activity | B32: BTL | C32: Mall Activity | D32: 5
A33: Mela | B33: BTL | C33: Mela | D33: 5
A34: Newspaper | B34: ATL | C34: Amar Ujala | D34: 5
C35: Daily Thanthi | D35: 5
C36: Dainik Bhaskar | D36: 5
C37: Dainik Jagran | D37: 5
C38: Hindustan Times | D38: 5
C39: Lokmat | D39: 5
C40: Loksatta | D40: 5
...

Sheet Instructions
A1: BGauss BTL — Activity Plan Template Guide
A2: ➡ Open the Activities sheet · Select Activity Name (col A) · Col B & D auto-update · Delete rows 4-6 · Save · Import
A3: Col | B3: Field | C3: Instructions
A4: A ★ | B4: Activity Name | C4: ⬇ DROPDOWN — Click the cell, a dropdown arrow appears, pick an activity. 23 activities from Activity Master. Pick this FIRST — col B and col D update automatically.
A5: B | B5: Subcategory | C5: ⬇ CASCADE DROPDOWN — Automatically shows ONLY the valid subcategories for whatever Activity Name you selected in col A. Click cell → dropdown arrow → pick.
A6: C | B6: QTY | C6: Whole number 1–20. See Subcategory Reference sheet for max per subcategory.
A7: D 🔒 | B7: Category (ATL/BTL) | C7: 🔒 AUTO-FILLED via formula — Do NOT type here. Shows ATL or BTL automatically as soon as you pick Activity Name in col A.
A8: E ★ | B8: Lead Target | C8: Expected number of leads. Positive whole number.
A9: F | B9: Sales % | C9: Optional. e.g. 3 means Retail = Lead × 3 ÷ 100. Auto-calculated on import.
A10: G ★ | B10: Retail Target | C10: Leave blank if Sales % filled (auto-calc on import). Otherwise type manually.
A11: H ★ | B11: Start Date | C11: Format: DD-MM-YYYY e.g. 01-07-2026
A12: I ★ | B12: End Date | C12: Format: DD-MM-YYYY Must be ≥ Start Date.
A13: J ★ | B13: Budget (₹) | C13: Numbers only. No ₹ symbol, no commas. e.g. 50000
A14: K | B14: Special Approval Budget | C14: Enter 0 if not needed.
... A18: O | B18: Remarks | C18: Optional notes for Checker/Approver.
A19: ⚠ DELETE rows 4, 5, 6 (EXAMPLE rows) before importing. They are samples only.
A20: ✔ Col D auto-fills ATL/BTL via VLOOKUP · Col B cascades via INDIRECT+MATCH · Generated 28-Jul-2026 · 23 activities
